2024-04-18 23:08:44,932 - PATROL: firebase - ERROR - Failed to create user - The user with the provided email already exists (EMAIL_EXISTS).
Traceback (most recent call last):
  File "D:\University of Southern California\CSCI578 SOFTWARE ARCHITECTURE\CODE\PATROL\venv\lib\site-packages\firebase_admin\_user_mgt.py", line 842, in _make_request
    return self.http_client.body_and_response(method, url, **kwargs)
  File "D:\University of Southern California\CSCI578 SOFTWARE ARCHITECTURE\CODE\PATROL\venv\lib\site-packages\firebase_admin\_http_client.py", line 127, in body_and_response
    resp = self.request(method, url, **kwargs)
  File "D:\University of Southern California\CSCI578 SOFTWARE ARCHITECTURE\CODE\PATROL\venv\lib\site-packages\firebase_admin\_http_client.py", line 119, in request
    resp.raise_for_status()
  File "D:\University of Southern California\CSCI578 SOFTWARE ARCHITECTURE\CODE\PATROL\venv\lib\site-packages\requests\models.py", line 1021, in raise_for_status
    raise HTTPError(http_error_msg, response=self)
requests.exceptions.HTTPError: 400 Client Error: Bad Request for url: https://identitytoolkit.googleapis.com/v1/projects/patrol-9398f/accounts

During handling of the above exception, another exception occurred:

Traceback (most recent call last):
  File "D:\University of Southern California\CSCI578 SOFTWARE ARCHITECTURE\CODE\PATROL\src\firebase.py", line 38, in create_user
    user = auth.create_user(
  File "D:\University of Southern California\CSCI578 SOFTWARE ARCHITECTURE\CODE\PATROL\venv\lib\site-packages\firebase_admin\auth.py", line 450, in create_user
    return client.create_user(**kwargs)
  File "D:\University of Southern California\CSCI578 SOFTWARE ARCHITECTURE\CODE\PATROL\venv\lib\site-packages\firebase_admin\_auth_client.py", line 313, in create_user
    uid = self._user_manager.create_user(**kwargs)
  File "D:\University of Southern California\CSCI578 SOFTWARE ARCHITECTURE\CODE\PATROL\venv\lib\site-packages\firebase_admin\_user_mgt.py", line 683, in create_user
    body, http_resp = self._make_request('post', '/accounts', json=payload)
  File "D:\University of Southern California\CSCI578 SOFTWARE ARCHITECTURE\CODE\PATROL\venv\lib\site-packages\firebase_admin\_user_mgt.py", line 844, in _make_request
    raise _auth_utils.handle_auth_backend_error(error)
firebase_admin._auth_utils.EmailAlreadyExistsError: The user with the provided email already exists (EMAIL_EXISTS).
2024-04-18 23:09:52,420 - PATROL: firebase - ERROR - Failed to create user - The user with the provided email already exists (EMAIL_EXISTS).
Traceback (most recent call last):
  File "D:\University of Southern California\CSCI578 SOFTWARE ARCHITECTURE\CODE\PATROL\venv\lib\site-packages\firebase_admin\_user_mgt.py", line 842, in _make_request
    return self.http_client.body_and_response(method, url, **kwargs)
  File "D:\University of Southern California\CSCI578 SOFTWARE ARCHITECTURE\CODE\PATROL\venv\lib\site-packages\firebase_admin\_http_client.py", line 127, in body_and_response
    resp = self.request(method, url, **kwargs)
  File "D:\University of Southern California\CSCI578 SOFTWARE ARCHITECTURE\CODE\PATROL\venv\lib\site-packages\firebase_admin\_http_client.py", line 119, in request
    resp.raise_for_status()
  File "D:\University of Southern California\CSCI578 SOFTWARE ARCHITECTURE\CODE\PATROL\venv\lib\site-packages\requests\models.py", line 1021, in raise_for_status
    raise HTTPError(http_error_msg, response=self)
requests.exceptions.HTTPError: 400 Client Error: Bad Request for url: https://identitytoolkit.googleapis.com/v1/projects/patrol-9398f/accounts

During handling of the above exception, another exception occurred:

Traceback (most recent call last):
  File "D:\University of Southern California\CSCI578 SOFTWARE ARCHITECTURE\CODE\PATROL\src\firebase.py", line 38, in create_user
    user = auth.create_user(
  File "D:\University of Southern California\CSCI578 SOFTWARE ARCHITECTURE\CODE\PATROL\venv\lib\site-packages\firebase_admin\auth.py", line 450, in create_user
    return client.create_user(**kwargs)
  File "D:\University of Southern California\CSCI578 SOFTWARE ARCHITECTURE\CODE\PATROL\venv\lib\site-packages\firebase_admin\_auth_client.py", line 313, in create_user
    uid = self._user_manager.create_user(**kwargs)
  File "D:\University of Southern California\CSCI578 SOFTWARE ARCHITECTURE\CODE\PATROL\venv\lib\site-packages\firebase_admin\_user_mgt.py", line 683, in create_user
    body, http_resp = self._make_request('post', '/accounts', json=payload)
  File "D:\University of Southern California\CSCI578 SOFTWARE ARCHITECTURE\CODE\PATROL\venv\lib\site-packages\firebase_admin\_user_mgt.py", line 844, in _make_request
    raise _auth_utils.handle_auth_backend_error(error)
firebase_admin._auth_utils.EmailAlreadyExistsError: The user with the provided email already exists (EMAIL_EXISTS).
2024-04-18 23:10:10,678 - PATROL: firebase - ERROR - Failed to create user - The user with the provided email already exists (EMAIL_EXISTS).
Traceback (most recent call last):
  File "D:\University of Southern California\CSCI578 SOFTWARE ARCHITECTURE\CODE\PATROL\venv\lib\site-packages\firebase_admin\_user_mgt.py", line 842, in _make_request
    return self.http_client.body_and_response(method, url, **kwargs)
  File "D:\University of Southern California\CSCI578 SOFTWARE ARCHITECTURE\CODE\PATROL\venv\lib\site-packages\firebase_admin\_http_client.py", line 127, in body_and_response
    resp = self.request(method, url, **kwargs)
  File "D:\University of Southern California\CSCI578 SOFTWARE ARCHITECTURE\CODE\PATROL\venv\lib\site-packages\firebase_admin\_http_client.py", line 119, in request
    resp.raise_for_status()
  File "D:\University of Southern California\CSCI578 SOFTWARE ARCHITECTURE\CODE\PATROL\venv\lib\site-packages\requests\models.py", line 1021, in raise_for_status
    raise HTTPError(http_error_msg, response=self)
requests.exceptions.HTTPError: 400 Client Error: Bad Request for url: https://identitytoolkit.googleapis.com/v1/projects/patrol-9398f/accounts

During handling of the above exception, another exception occurred:

Traceback (most recent call last):
  File "D:\University of Southern California\CSCI578 SOFTWARE ARCHITECTURE\CODE\PATROL\src\firebase.py", line 38, in create_user
    user = auth.create_user(
  File "D:\University of Southern California\CSCI578 SOFTWARE ARCHITECTURE\CODE\PATROL\venv\lib\site-packages\firebase_admin\auth.py", line 450, in create_user
    return client.create_user(**kwargs)
  File "D:\University of Southern California\CSCI578 SOFTWARE ARCHITECTURE\CODE\PATROL\venv\lib\site-packages\firebase_admin\_auth_client.py", line 313, in create_user
    uid = self._user_manager.create_user(**kwargs)
  File "D:\University of Southern California\CSCI578 SOFTWARE ARCHITECTURE\CODE\PATROL\venv\lib\site-packages\firebase_admin\_user_mgt.py", line 683, in create_user
    body, http_resp = self._make_request('post', '/accounts', json=payload)
  File "D:\University of Southern California\CSCI578 SOFTWARE ARCHITECTURE\CODE\PATROL\venv\lib\site-packages\firebase_admin\_user_mgt.py", line 844, in _make_request
    raise _auth_utils.handle_auth_backend_error(error)
firebase_admin._auth_utils.EmailAlreadyExistsError: The user with the provided email already exists (EMAIL_EXISTS).
2024-04-18 23:14:32,713 - PATROL: firebase - ERROR - Failed to create user - The user with the provided email already exists (EMAIL_EXISTS).
Traceback (most recent call last):
  File "D:\University of Southern California\CSCI578 SOFTWARE ARCHITECTURE\CODE\PATROL\venv\lib\site-packages\firebase_admin\_user_mgt.py", line 842, in _make_request
    return self.http_client.body_and_response(method, url, **kwargs)
  File "D:\University of Southern California\CSCI578 SOFTWARE ARCHITECTURE\CODE\PATROL\venv\lib\site-packages\firebase_admin\_http_client.py", line 127, in body_and_response
    resp = self.request(method, url, **kwargs)
  File "D:\University of Southern California\CSCI578 SOFTWARE ARCHITECTURE\CODE\PATROL\venv\lib\site-packages\firebase_admin\_http_client.py", line 119, in request
    resp.raise_for_status()
  File "D:\University of Southern California\CSCI578 SOFTWARE ARCHITECTURE\CODE\PATROL\venv\lib\site-packages\requests\models.py", line 1021, in raise_for_status
    raise HTTPError(http_error_msg, response=self)
requests.exceptions.HTTPError: 400 Client Error: Bad Request for url: https://identitytoolkit.googleapis.com/v1/projects/patrol-9398f/accounts

During handling of the above exception, another exception occurred:

Traceback (most recent call last):
  File "D:\University of Southern California\CSCI578 SOFTWARE ARCHITECTURE\CODE\PATROL\src\firebase.py", line 38, in create_user
    user = auth.create_user(
  File "D:\University of Southern California\CSCI578 SOFTWARE ARCHITECTURE\CODE\PATROL\venv\lib\site-packages\firebase_admin\auth.py", line 450, in create_user
    return client.create_user(**kwargs)
  File "D:\University of Southern California\CSCI578 SOFTWARE ARCHITECTURE\CODE\PATROL\venv\lib\site-packages\firebase_admin\_auth_client.py", line 313, in create_user
    uid = self._user_manager.create_user(**kwargs)
  File "D:\University of Southern California\CSCI578 SOFTWARE ARCHITECTURE\CODE\PATROL\venv\lib\site-packages\firebase_admin\_user_mgt.py", line 683, in create_user
    body, http_resp = self._make_request('post', '/accounts', json=payload)
  File "D:\University of Southern California\CSCI578 SOFTWARE ARCHITECTURE\CODE\PATROL\venv\lib\site-packages\firebase_admin\_user_mgt.py", line 844, in _make_request
    raise _auth_utils.handle_auth_backend_error(error)
firebase_admin._auth_utils.EmailAlreadyExistsError: The user with the provided email already exists (EMAIL_EXISTS).
